<?xml version="1.0"?>
<robot xmlns:xacro="http://www.ros.org/wiki/xacro">
  <!-- Parallel two-finger gripper mounted on the UR tool flange. -->
  <xacro:macro name="parallel_gripper" params="parent">
    <link name="gripper_base">
      <inertial>
        <mass value="0.35"/>
        <origin xyz="0 0 0" rpy="0 0 0"/>
        <inertia ixx="0.0004" ixy="0" ixz="0" iyy="0.0002" iyz="0" izz="0.0005"/>
      </inertial>
      <visual>
        <geometry>
          <box size="0.045 0.13 0.04"/>
        </geometry>
        <material name="gripper_dark_grey">
          <color rgba="0.22 0.22 0.24 1.0"/>
        </material>
      </visual>
    </link>

    <joint name="gripper_base_joint" type="fixed">
      <parent link="${parent}"/>
      <child link="gripper_base"/>
      <origin xyz="0 0 0.022" rpy="0 0 0"/>
    </joint>

    <link name="gripper_left_finger">
      <inertial>
        <mass value="0.06"/>
        <origin xyz="0 0 0" rpy="0 0 0"/>
        <inertia ixx="0.00003" ixy="0" ixz="0" iyy="0.00003" iyz="0" izz="0.00001"/>
      </inertial>
      <visual>
        <geometry>
          <box size="0.025 0.012 0.075"/>
        </geometry>
        <material name="gripper_light_grey">
          <color rgba="0.78 0.80 0.82 1.0"/>
        </material>
      </visual>
    </link>

    <joint name="gripper_left_finger_joint" type="prismatic">
      <parent link="gripper_base"/>
      <child link="gripper_left_finger"/>
      <origin xyz="0 0.052 0.0575" rpy="0 0 0"/>
      <axis xyz="0 -1 0"/>
      <limit lower="0.0" upper="0.035" effort="60.0" velocity="0.3"/>
    </joint>

    <link name="gripper_right_finger">
      <inertial>
        <mass value="0.06"/>
        <origin xyz="0 0 0" rpy="0 0 0"/>
        <inertia ixx="0.00003" ixy="0" ixz="0" iyy="0.00003" iyz="0" izz="0.00001"/>
      </inertial>
      <visual>
        <geometry>
          <box size="0.025 0.012 0.075"/>
        </geometry>
        <material name="gripper_light_grey">
          <color rgba="0.78 0.80 0.82 1.0"/>
        </material>
      </visual>
    </link>

    <joint name="gripper_right_finger_joint" type="prismatic">
      <parent link="gripper_base"/>
      <child link="gripper_right_finger"/>
      <origin xyz="0 -0.052 0.0575" rpy="0 0 0"/>
      <axis xyz="0 1 0"/>
      <limit lower="0.0" upper="0.035" effort="60.0" velocity="0.3"/>
    </joint>

    <link name="gripper_tcp"/>

    <joint name="gripper_tcp_joint" type="fixed">
      <parent link="${parent}"/>
      <child link="gripper_tcp"/>
      <origin xyz="0 0 0.105" rpy="0 0 0"/>
    </joint>
  </xacro:macro>
</robot>
